{
 "cells": [
  {
   "cell_type": "markdown",
   "metadata": {},
   "source": [
    "# Part 04 - Errors (Fantastic exceptions and where to find them)\n",
    "\n",
    "As you're new programmers, you will spend most of your time handling errors. Sometimes, you even want to make errors of your own. Fortunately, you can teach python to handle errors or make them for you. Let's deliberately try something stupid and see what happens"
   ]
  },
  {
   "cell_type": "code",
   "execution_count": 7,
   "metadata": {
    "collapsed": false
   },
   "outputs": [
    {
     "ename": "ValueError",
     "evalue": "math domain error",
     "output_type": "error",
     "traceback": [
      "\u001b[0;31m---------------------------------------------------------------------------\u001b[0m",
      "\u001b[0;31mValueError\u001b[0m                                Traceback (most recent call last)",
      "\u001b[0;32m<ipython-input-7-e1602d0b90c7>\u001b[0m in \u001b[0;36m<module>\u001b[0;34m()\u001b[0m\n\u001b[1;32m      1\u001b[0m \u001b[0;32mimport\u001b[0m \u001b[0mmath\u001b[0m\u001b[0;34m\u001b[0m\u001b[0m\n\u001b[1;32m      2\u001b[0m \u001b[0;31m#logarithms of negative numbers are not valid\u001b[0m\u001b[0;34m\u001b[0m\u001b[0;34m\u001b[0m\u001b[0m\n\u001b[0;32m----> 3\u001b[0;31m \u001b[0mmath\u001b[0m\u001b[0;34m.\u001b[0m\u001b[0mlog\u001b[0m\u001b[0;34m(\u001b[0m\u001b[0;34m-\u001b[0m\u001b[0;36m1\u001b[0m\u001b[0;34m)\u001b[0m\u001b[0;34m\u001b[0m\u001b[0m\n\u001b[0m",
      "\u001b[0;31mValueError\u001b[0m: math domain error"
     ]
    }
   ],
   "source": [
    "import math\n",
    "#logarithms of negative numbers are not valid\n",
    "math.log(-1) "
   ]
  },
  {
   "cell_type": "markdown",
   "metadata": {},
   "source": [
    "Here we see something called `ValueError`, which has a `math domain error` message associated with it. Where did this come from?\n",
    "\n",
    "When bad values are passed to a function, it can't return a value as that might be misinterpreted as the answer. Instead, we raise an exception. Exceptions are not return values but instead bubble up the stack until they are caught or they come out of the main scope where they cause python to exit.\n",
    "\n",
    "The stack is all the functions that python has had to enter to get to the current line of execution. Going up the stack, python looks for anything that might catch the exception. Lets see how that's done, "
   ]
  },
  {
   "cell_type": "code",
   "execution_count": 9,
   "metadata": {
    "collapsed": false
   },
   "outputs": [
    {
     "name": "stdout",
     "output_type": "stream",
     "text": [
      "math domain error\n",
      "<class 'ValueError'>\n",
      "ValueError('math domain error',)\n"
     ]
    }
   ],
   "source": [
    "try:\n",
    "    math.log(-1)\n",
    "except Exception as e:\n",
    "    print(e)\n",
    "    print(type(e))\n",
    "    print(repr(e))"
   ]
  },
  {
   "cell_type": "markdown",
   "metadata": {},
   "source": [
    "If any commands within a `try` block raise an exception, and the exception rises up to the `try` block then it will be caught and the code in the `except:` block is run. Above, we just print the exception, the type of the exception, and we use the `repr` command which returns the a python command which will generate the object passed as an argument.\n",
    "\n",
    "The `try...catch` block above catches all exceptions (as all exceptions derive from the `Exception` class). We can actually catch specfic exceptions and deal with them in a special way,"
   ]
  },
  {
   "cell_type": "code",
   "execution_count": 10,
   "metadata": {
    "collapsed": false
   },
   "outputs": [
    {
     "name": "stdout",
     "output_type": "stream",
     "text": [
      "Bad value used\n"
     ]
    }
   ],
   "source": [
    "try:\n",
    "    math.log(-1)\n",
    "except ValueError as e:\n",
    "    print(\"Bad value used\")\n",
    "except Exception as e:\n",
    "    print(\"Some other error happened!\", e)"
   ]
  },
  {
   "cell_type": "markdown",
   "metadata": {},
   "source": [
    "How do we raise exceptions ourselves? We just write raise, then use an exception type:"
   ]
  },
  {
   "cell_type": "code",
   "execution_count": 12,
   "metadata": {
    "collapsed": false
   },
   "outputs": [
    {
     "ename": "RuntimeError",
     "evalue": "My own exception",
     "output_type": "error",
     "traceback": [
      "\u001b[0;31m---------------------------------------------------------------------------\u001b[0m",
      "\u001b[0;31mRuntimeError\u001b[0m                              Traceback (most recent call last)",
      "\u001b[0;32m<ipython-input-12-ceee3981c85f>\u001b[0m in \u001b[0;36m<module>\u001b[0;34m()\u001b[0m\n\u001b[0;32m----> 1\u001b[0;31m \u001b[0;32mraise\u001b[0m \u001b[0mRuntimeError\u001b[0m\u001b[0;34m(\u001b[0m\u001b[0;34m\"My own exception\"\u001b[0m\u001b[0;34m)\u001b[0m\u001b[0;34m\u001b[0m\u001b[0m\n\u001b[0m",
      "\u001b[0;31mRuntimeError\u001b[0m: My own exception"
     ]
    }
   ],
   "source": [
    "raise RuntimeError(\"My own exception\")"
   ]
  },
  {
   "cell_type": "markdown",
   "metadata": {},
   "source": [
    "Lets look how you might use it to improve our prime number function,"
   ]
  },
  {
   "cell_type": "code",
   "execution_count": 28,
   "metadata": {
    "collapsed": false
   },
   "outputs": [
    {
     "name": "stdout",
     "output_type": "stream",
     "text": [
      "2147483647 True\n",
      "3.0 True\n"
     ]
    },
    {
     "ename": "ValueError",
     "evalue": "isPrime cannot accept fractional floating values",
     "output_type": "error",
     "traceback": [
      "\u001b[0;31m---------------------------------------------------------------------------\u001b[0m",
      "\u001b[0;31mValueError\u001b[0m                                Traceback (most recent call last)",
      "\u001b[0;32m<ipython-input-28-0f45854d5b3d>\u001b[0m in \u001b[0;36m<module>\u001b[0;34m()\u001b[0m\n\u001b[1;32m     20\u001b[0m \u001b[0;34m\u001b[0m\u001b[0m\n\u001b[1;32m     21\u001b[0m \u001b[0;31m#Errors which raise exceptions!\u001b[0m\u001b[0;34m\u001b[0m\u001b[0;34m\u001b[0m\u001b[0m\n\u001b[0;32m---> 22\u001b[0;31m \u001b[0misPrime\u001b[0m\u001b[0;34m(\u001b[0m\u001b[0;36m2.2\u001b[0m\u001b[0;34m)\u001b[0m\u001b[0;34m\u001b[0m\u001b[0m\n\u001b[0m\u001b[1;32m     23\u001b[0m \u001b[0misPrime\u001b[0m\u001b[0;34m(\u001b[0m\u001b[0;34m\"Not an integer\"\u001b[0m\u001b[0;34m)\u001b[0m\u001b[0;34m\u001b[0m\u001b[0m\n",
      "\u001b[0;32m<ipython-input-28-0f45854d5b3d>\u001b[0m in \u001b[0;36misPrime\u001b[0;34m(n)\u001b[0m\n\u001b[1;32m      6\u001b[0m             \u001b[0mn\u001b[0m \u001b[0;34m=\u001b[0m \u001b[0mint\u001b[0m\u001b[0;34m(\u001b[0m\u001b[0mn\u001b[0m\u001b[0;34m)\u001b[0m\u001b[0;34m\u001b[0m\u001b[0m\n\u001b[1;32m      7\u001b[0m         \u001b[0;32melse\u001b[0m\u001b[0;34m:\u001b[0m\u001b[0;34m\u001b[0m\u001b[0m\n\u001b[0;32m----> 8\u001b[0;31m             \u001b[0;32mraise\u001b[0m \u001b[0mValueError\u001b[0m\u001b[0;34m(\u001b[0m\u001b[0;34m\"isPrime cannot accept fractional floating values\"\u001b[0m\u001b[0;34m)\u001b[0m\u001b[0;34m\u001b[0m\u001b[0m\n\u001b[0m\u001b[1;32m      9\u001b[0m \u001b[0;34m\u001b[0m\u001b[0m\n\u001b[1;32m     10\u001b[0m     \u001b[0;32mif\u001b[0m \u001b[0;32mnot\u001b[0m \u001b[0misinstance\u001b[0m\u001b[0;34m(\u001b[0m\u001b[0mn\u001b[0m\u001b[0;34m,\u001b[0m \u001b[0mint\u001b[0m\u001b[0;34m)\u001b[0m\u001b[0;34m:\u001b[0m\u001b[0;34m\u001b[0m\u001b[0m\n",
      "\u001b[0;31mValueError\u001b[0m: isPrime cannot accept fractional floating values"
     ]
    }
   ],
   "source": [
    "import math\n",
    "def isPrime(n):\n",
    "    # Perform sanity checks on the input\n",
    "    if isinstance(n, float):\n",
    "        if n.is_integer():\n",
    "            n = int(n)\n",
    "        else:\n",
    "            raise ValueError(\"isPrime cannot accept fractional floating values\")\n",
    "    \n",
    "    if not isinstance(n, int):\n",
    "        raise ValueError(\"isPrime can only accept integer arguments\")\n",
    "        \n",
    "    for div in range(2,int(math.sqrt(n))):\n",
    "        if n % div == 0:\n",
    "            return False\n",
    "    return True\n",
    "\n",
    "print(2**31-1, isPrime(2**31-1))\n",
    "print(3.0, isPrime(3.0))\n",
    "\n",
    "#Errors which raise exceptions!\n",
    "isPrime(2.2)\n",
    "isPrime(\"Not an integer\")"
   ]
  },
  {
   "cell_type": "markdown",
   "metadata": {},
   "source": [
    "We now get nice error messages when we abuse our `isPrime` function. Great! Lets look at a time where we need to use exceptions."
   ]
  },
  {
   "cell_type": "code",
   "execution_count": null,
   "metadata": {
    "collapsed": true
   },
   "outputs": [],
   "source": []
  }
 ],
 "metadata": {
  "kernelspec": {
   "display_name": "Python 3",
   "language": "python",
   "name": "python3"
  },
  "language_info": {
   "codemirror_mode": {
    "name": "ipython",
    "version": 3
   },
   "file_extension": ".py",
   "mimetype": "text/x-python",
   "name": "python",
   "nbconvert_exporter": "python",
   "pygments_lexer": "ipython3",
   "version": "3.5.3"
  }
 },
 "nbformat": 4,
 "nbformat_minor": 2
}
